{"nbformat":4,"nbformat_minor":0,"metadata":{"colab":{"provenance":[],"authorship_tag":"ABX9TyP3hoPQY7JbLWRFrT4yE7kb"},"kernelspec":{"name":"python3","display_name":"Python 3"},"language_info":{"name":"python"}},"cells":[{"cell_type":"code","source":["!pip install streamlit -q"],"metadata":{"id":"oVBnenW-Y1bi","executionInfo":{"status":"ok","timestamp":1700260506304,"user_tz":0,"elapsed":5882,"user":{"displayName":"Felihle Ncongwane","userId":"04062938931593930847"}}},"execution_count":4,"outputs":[]},{"cell_type":"code","source":["!wget q -O - ipv4.icanhazip.com"],"metadata":{"id":"YieXf9DDY4wI","colab":{"base_uri":"https://localhost:8080/"},"executionInfo":{"status":"ok","timestamp":1700260512242,"user_tz":0,"elapsed":621,"user":{"displayName":"Felihle Ncongwane","userId":"04062938931593930847"}},"outputId":"8f5ba832-6320-4a62-fbf9-e7f74cdc90dc"},"execution_count":5,"outputs":[{"output_type":"stream","name":"stdout","text":["--2023-11-17 22:35:11--  http://q/\n","Resolving q (q)... failed: Name or service not known.\n","wget: unable to resolve host address ‘q’\n","--2023-11-17 22:35:11--  http://ipv4.icanhazip.com/\n","Resolving ipv4.icanhazip.com (ipv4.icanhazip.com)... 104.18.114.97, 104.18.115.97\n","Connecting to ipv4.icanhazip.com (ipv4.icanhazip.com)|104.18.114.97|:80... connected.\n","HTTP request sent, awaiting response... 200 OK\n","Length: 13 [text/plain]\n","Saving to: ‘STDOUT’\n","\n","\r-                     0%[                    ]       0  --.-KB/s               34.23.215.52\n","\r-                   100%[===================>]      13  --.-KB/s    in 0s      \n","\n","2023-11-17 22:35:11 (2.18 MB/s) - written to stdout [13/13]\n","\n","FINISHED --2023-11-17 22:35:11--\n","Total wall clock time: 0.2s\n","Downloaded: 1 files, 13 in 0s (2.18 MB/s)\n"]}]},{"cell_type":"code","source":["!streamlit run app.py & npx localtunnel --port 8501"],"metadata":{"id":"X6PHowhWY8GU","colab":{"base_uri":"https://localhost:8080/"},"outputId":"9c0e070d-6ee9-470a-bcfb-a71296e443d2"},"execution_count":null,"outputs":[{"metadata":{"tags":null},"name":"stdout","output_type":"stream","text":["\n","Collecting usage statistics. To deactivate, set browser.gatherUsageStats to False.\n","\u001b[0m\n","\u001b[0m\n","\u001b[34m\u001b[1m  You can now view your Streamlit app in your browser.\u001b[0m\n","\u001b[0m\n","\u001b[34m  Network URL: \u001b[0m\u001b[1mhttp://172.28.0.12:8501\u001b[0m\n","\u001b[34m  External URL: \u001b[0m\u001b[1mhttp://34.23.215.52:8501\u001b[0m\n","\u001b[0m\n","\u001b[K\u001b[?25hnpx: installed 22 in 4.243s\n","your url is: https://warm-dots-raise.loca.lt\n","2023-11-17 22:36:10.790801: E tensorflow/compiler/xla/stream_executor/cuda/cuda_dnn.cc:9342] Unable to register cuDNN factory: Attempting to register factory for plugin cuDNN when one has already been registered\n","2023-11-17 22:36:10.790859: E tensorflow/compiler/xla/stream_executor/cuda/cuda_fft.cc:609] Unable to register cuFFT factory: Attempting to register factory for plugin cuFFT when one has already been registered\n","2023-11-17 22:36:10.790892: E tensorflow/compiler/xla/stream_executor/cuda/cuda_blas.cc:1518] Unable to register cuBLAS factory: Attempting to register factory for plugin cuBLAS when one has already been registered\n","2023-11-17 22:36:12.212973: W tensorflow/compiler/tf2tensorrt/utils/py_utils.cc:38] TF-TRT Warning: Could not find TensorRT\n","2023-11-17 22:37:32.683 Uncaught app exception\n","Traceback (most recent call last):\n","  File \"/usr/local/lib/python3.10/dist-packages/streamlit/runtime/scriptrunner/script_runner.py\", line 534, in _run_script\n","    exec(code, module.__dict__)\n","  File \"/content/app.py\", line 98, in <module>\n","    main()\n","  File \"/content/app.py\", line 92, in main\n","    predictions = predict_churn(new_data)\n","  File \"/content/app.py\", line 56, in predict_churn\n","    preprocessed_data = preprocess_data(data)\n","  File \"/content/app.py\", line 24, in preprocess_data\n","    data = data.drop('customerID', axis='columns')\n","  File \"/usr/local/lib/python3.10/dist-packages/pandas/util/_decorators.py\", line 331, in wrapper\n","    return func(*args, **kwargs)\n","  File \"/usr/local/lib/python3.10/dist-packages/pandas/core/frame.py\", line 5399, in drop\n","    return super().drop(\n","  File \"/usr/local/lib/python3.10/dist-packages/pandas/util/_decorators.py\", line 331, in wrapper\n","    return func(*args, **kwargs)\n","  File \"/usr/local/lib/python3.10/dist-packages/pandas/core/generic.py\", line 4505, in drop\n","    obj = obj._drop_axis(labels, axis, level=level, errors=errors)\n","  File \"/usr/local/lib/python3.10/dist-packages/pandas/core/generic.py\", line 4546, in _drop_axis\n","    new_axis = axis.drop(labels, errors=errors)\n","  File \"/usr/local/lib/python3.10/dist-packages/pandas/core/indexes/base.py\", line 6934, in drop\n","    raise KeyError(f\"{list(labels[mask])} not found in axis\")\n","KeyError: \"['customerID'] not found in axis\"\n","1/1 [==============================] - 0s 123ms/step\n","1/1 [==============================] - 0s 79ms/step\n","1/1 [==============================] - 0s 53ms/step\n","1/1 [==============================] - 0s 55ms/step\n","WARNING:tensorflow:5 out of the last 5 calls to <function Model.make_predict_function.<locals>.predict_function at 0x7965f4367d00> triggered tf.function retracing. Tracing is expensive and the excessive number of tracings could be due to (1) creating @tf.function repeatedly in a loop, (2) passing tensors with different shapes, (3) passing Python objects instead of tensors. For (1), please define your @tf.function outside of the loop. For (2), @tf.function has reduce_retracing=True option that can avoid unnecessary retracing. For (3), please refer to https://www.tensorflow.org/guide/function#controlling_retracing and https://www.tensorflow.org/api_docs/python/tf/function for  more details.\n","1/1 [==============================] - 0s 55ms/step\n","WARNING:tensorflow:6 out of the last 6 calls to <function Model.make_predict_function.<locals>.predict_function at 0x7965f4367c70> triggered tf.function retracing. Tracing is expensive and the excessive number of tracings could be due to (1) creating @tf.function repeatedly in a loop, (2) passing tensors with different shapes, (3) passing Python objects instead of tensors. For (1), please define your @tf.function outside of the loop. For (2), @tf.function has reduce_retracing=True option that can avoid unnecessary retracing. For (3), please refer to https://www.tensorflow.org/guide/function#controlling_retracing and https://www.tensorflow.org/api_docs/python/tf/function for  more details.\n","1/1 [==============================] - 0s 79ms/step\n","1/1 [==============================] - 0s 89ms/step\n","1/1 [==============================] - 0s 82ms/step\n","1/1 [==============================] - 0s 78ms/step\n","1/1 [==============================] - 0s 52ms/step\n","1/1 [==============================] - 0s 81ms/step\n","1/1 [==============================] - 0s 55ms/step\n","1/1 [==============================] - 0s 53ms/step\n","1/1 [==============================] - 0s 64ms/step\n","1/1 [==============================] - 0s 56ms/step\n","1/1 [==============================] - 0s 78ms/step\n","1/1 [==============================] - 0s 55ms/step\n","1/1 [==============================] - 0s 54ms/step\n","1/1 [==============================] - 0s 81ms/step\n","1/1 [==============================] - 0s 53ms/step\n","1/1 [==============================] - 0s 53ms/step\n","1/1 [==============================] - 0s 52ms/step\n","1/1 [==============================] - 0s 79ms/step\n","1/1 [==============================] - 0s 79ms/step\n","1/1 [==============================] - 0s 83ms/step\n","1/1 [==============================] - 0s 82ms/step\n","1/1 [==============================] - 0s 52ms/step\n","1/1 [==============================] - 0s 54ms/step\n","1/1 [==============================] - 0s 53ms/step\n","1/1 [==============================] - 0s 52ms/step\n","1/1 [==============================] - 0s 54ms/step\n","2023-11-17 23:24:06.858 Uncaught app exception\n","Traceback (most recent call last):\n","  File \"/usr/local/lib/python3.10/dist-packages/streamlit/runtime/scriptrunner/script_runner.py\", line 534, in _run_script\n","    exec(code, module.__dict__)\n","  File \"/content/app.py\", line 102, in <module>\n","    main()\n","  File \"/content/app.py\", line 92, in main\n","    predictions = predict_churn(new_data)\n","UnboundLocalError: local variable 'new_data' referenced before assignment\n","2023-11-17 23:24:38.043 Uncaught app exception\n","Traceback (most recent call last):\n","  File \"/usr/local/lib/python3.10/dist-packages/streamlit/runtime/scriptrunner/script_runner.py\", line 534, in _run_script\n","    exec(code, module.__dict__)\n","  File \"/content/app.py\", line 102, in <module>\n","    main()\n","  File \"/content/app.py\", line 92, in main\n","    predictions = predict_churn(new_data)\n","UnboundLocalError: local variable 'new_data' referenced before assignment\n","1/1 [==============================] - 0s 53ms/step\n","1/1 [==============================] - 0s 52ms/step\n","1/1 [==============================] - 0s 56ms/step\n","1/1 [==============================] - 0s 52ms/step\n","1/1 [==============================] - 0s 52ms/step\n","1/1 [==============================] - 0s 54ms/step\n","1/1 [==============================] - 0s 52ms/step\n","1/1 [==============================] - 0s 54ms/step\n","1/1 [==============================] - 0s 55ms/step\n","1/1 [==============================] - 0s 54ms/step\n","2023-11-17 23:34:46.096 Uncaught app exception\n","Traceback (most recent call last):\n","  File \"/usr/local/lib/python3.10/dist-packages/streamlit/runtime/scriptrunner/script_runner.py\", line 534, in _run_script\n","    exec(code, module.__dict__)\n","  File \"/content/app.py\", line 102, in <module>\n","    main()\n","  File \"/content/app.py\", line 92, in main\n","    predictions = predict_churn(new_data)\n","UnboundLocalError: local variable 'new_data' referenced before assignment\n","1/1 [==============================] - 0s 55ms/step\n","1/1 [==============================] - 0s 51ms/step\n","1/1 [==============================] - 0s 55ms/step\n","1/1 [==============================] - 0s 52ms/step\n","1/1 [==============================] - 0s 51ms/step\n","2023-11-18 00:14:06.162 Uncaught app exception\n","Traceback (most recent call last):\n","  File \"/usr/local/lib/python3.10/dist-packages/streamlit/runtime/scriptrunner/script_runner.py\", line 534, in _run_script\n","    exec(code, module.__dict__)\n","  File \"/content/app.py\", line 99, in <module>\n","    main()\n","  File \"/content/app.py\", line 90, in main\n","    churn_probability = predictions[0][2]\n","IndexError: index 2 is out of bounds for axis 0 with size 1\n","1/1 [==============================] - 0s 51ms/step\n","2023-11-18 00:14:40.821 Uncaught app exception\n","Traceback (most recent call last):\n","  File \"/usr/local/lib/python3.10/dist-packages/streamlit/runtime/scriptrunner/script_runner.py\", line 534, in _run_script\n","    exec(code, module.__dict__)\n","  File \"/content/app.py\", line 99, in <module>\n","    main()\n","  File \"/content/app.py\", line 90, in main\n","    churn_probability = predictions[0][1]\n","IndexError: index 1 is out of bounds for axis 0 with size 1\n","1/1 [==============================] - 0s 75ms/step\n","1/1 [==============================] - 0s 76ms/step\n","1/1 [==============================] - 0s 54ms/step\n","1/1 [==============================] - 0s 53ms/step\n","2023-11-18 00:24:15.116 Uncaught app exception\n","Traceback (most recent call last):\n","  File \"/usr/local/lib/python3.10/dist-packages/streamlit/runtime/scriptrunner/script_runner.py\", line 534, in _run_script\n","    exec(code, module.__dict__)\n","  File \"/content/app.py\", line 99, in <module>\n","    main()\n","  File \"/content/app.py\", line 88, in main\n","    predictions = predict_churn(new_data)\n","  File \"/content/app.py\", line 54, in predict_churn\n","    y_pred = model.predict(X)\n","  File \"/usr/local/lib/python3.10/dist-packages/keras/src/utils/traceback_utils.py\", line 70, in error_handler\n","    raise e.with_traceback(filtered_tb) from None\n","  File \"/tmp/__autograph_generated_fileylqu_fu9.py\", line 15, in tf__predict_function\n","    retval_ = ag__.converted_call(ag__.ld(step_function), (ag__.ld(self), ag__.ld(iterator)), None, fscope)\n","ValueError: in user code:\n","\n","    File \"/usr/local/lib/python3.10/dist-packages/keras/src/engine/training.py\", line 2416, in predict_function  *\n","        return step_function(self, iterator)\n","    File \"/usr/local/lib/python3.10/dist-packages/keras/src/engine/training.py\", line 2401, in step_function  **\n","        outputs = model.distribute_strategy.run(run_step, args=(data,))\n","    File \"/usr/local/lib/python3.10/dist-packages/keras/src/engine/training.py\", line 2389, in run_step  **\n","        outputs = model.predict_step(data)\n","    File \"/usr/local/lib/python3.10/dist-packages/keras/src/engine/training.py\", line 2357, in predict_step\n","        return self(x, training=False)\n","    File \"/usr/local/lib/python3.10/dist-packages/keras/src/utils/traceback_utils.py\", line 70, in error_handler\n","        raise e.with_traceback(filtered_tb) from None\n","    File \"/usr/local/lib/python3.10/dist-packages/keras/src/engine/input_spec.py\", line 298, in assert_input_compatibility\n","        raise ValueError(\n","\n","    ValueError: Input 0 of layer \"model_2\" is incompatible with the layer: expected shape=(None, 13), found shape=(None, 10)\n","\n","1/1 [==============================] - 0s 54ms/step\n","1/1 [==============================] - 0s 53ms/step\n"]}]}]}